Workbook
Name ActivityNames: hiddenData!$A$1:$A$15
Name Bottleneck0: hiddenData!$H$1:$H$15
Name Bottleneck1: #REF!
Name Consumption0: hiddenData!$F$1:$F$8
Name Consumption1: #REF!
Name Resources: hiddenData!$F$9:$F$16
Name TotalCosts0: hiddenData!$B$1:$B$15
Name TotalCosts1: #REF!
Name TotalTime0: hiddenData!$D$1:$D$15
Name TotalTime1: #REF!

Sheet Overview
A1: Report | B1: Simulation
A2: Date | B2: 5/22/26
A3: Time | B3: 9:17 PM
A4: User | B4: Carlo Garcia
A5: Process | B5: AS-IS - Proceso de gestión de pedidos de INDUPRO S.A.
A7: Used scenario | B7: Duration in days | C7: Total cycle time | D7: Resource consumption | E7: Bottlenecks
A8: Escenario 1 AS-IS | B8: 5 | C8: 10.701389 | D8: 4.5069444 | E8: Analista de finanzas

Sheet Costs
A1: Report | B1: Simulation
A2: Date | B2: 5/22/26
A3: Time | B3: 9:17 PM
A4: User | B4: Carlo Garcia
A5: Process | B5: AS-IS - Proceso de gestión de pedidos de INDUPRO S.A.
A7: Execution costs of a process instance are the sum of fixed activity costs and resources costs. The latter ones are computed using defined responsibilities and activity execution durations. The following table shows selected process instance costs as well as the total sum of all costs:
A10: Used scenario | B10: Duration in days | C10: Average | D10: Minimum | E10: Maximum | F10: Total costs
A11: Escenario 1 AS-IS | B11: 5 | C11: 64.38 | D11: 62.17 | E11: 101.92 | F11: 1214.92
A13: The following table shows the costs caused by every activity of your process:
A15: Task | B15: Used scenario | C15: Duration in days | D15: Completed instances | E15: Average | F15: Minimum | G15: Maximum | H15: Total costs
A16: Recibir solicitud del cliente | B16: Escenario 1 AS-IS | C16: 5 | D16: 20 | E16: 6 | F16: 6 | G16: 6 | H16: 120
A17: Validar datos del pedido | B17: Escenario 1 AS-IS | C17: 5 | D17: 20 | E17: 9 | F17: 9 | G17: 9 | H17: 180
A18: Verificar crédito del cliente | B18: Escenario 1 AS-IS | C18: 5 | D18: 19 | E18: 13 | F18: 13 | G18: 13 | H18: 247
A19: Consultar disponibilidad de stock en bodega | B19: Escenario 1 AS-IS | C19: 5 | D19: 19 | E19: 8.33 | F19: 8.33 | G19: 8.33 | H19: 158.33
A20: Verificar stock | B20: Escenario 1 AS-IS | C20: 5 | D20: 19 | E20: 0.83 | F20: 0.83 | G20: 0.83 | H20: 15.83
A21: Confirmar pedido al cliente | B21: Escenario 1 AS-IS | C21: 5 | D21: 18 | E21: 4 | F21: 4 | G21: 4 | H21: 72
A22: Programar orden de producción | B22: Escenario 1 AS-IS | C22: 5 | D22: 1 | E22: 9.33 | F22: 9.33 | G22: 9.33 | H22: 9.33
A23: Fabricar producto | B23: Escenario 1 AS-IS | C23: 5 | D23: 1 | E23: 16 | F23: 16 | G23: 16 | H23: 16
A24: Inspeccionar y liberar calidad | B24: Escenario 1 AS-IS | C24: 5 | D24: 1 | E24: 5.5 | F24: 5.5 | G24: 5.5 | H24: 5.5
A25: Verificar calidad | B25: Escenario 1 AS-IS | C25: 5 | D25: 1 | E25: 0.92 | F25: 0.92 | G25: 0.92 | H25: 0.92
A26: Reprocesar lote | B26: Escenario 1 AS-IS | C26: 5 | D26: 1 | E26: 12 | F26: 12 | G26: 12 | H26: 12
A27: Empacar y preparar para despacho | B27: Escenario 1 AS-IS | C27: 5 | D27: 18 | E27: 4.17 | F27: 4.17 | G27: 4.17 | H27: 75
... A30: Generar y enviar factura | B30: Escenario 1 AS-IS | C30: 5 | D30: 18 | E30: 4.33 | F30: 4.33 | G30: 4.33 | H30: 78
A32: Legend
A33: All values are relative to the highest value
A34: Latest run | B34: Previous run
A35: 100% | B35: 100%
A36: >87.5% | B36: >87.5%
A37: >75% | B37: >75%
A38: >62.5% | B38: >62.5%
A39: >50% | B39: >50%
A40: <=50% or smallest value | B40: <=50% or smallest value

Sheet Total cost chart
A1: Report | B1: Simulation
A2: Date | B2: 5/22/26
A3: Time | B3: 9:17 PM
A4: User | B4: Carlo Garcia
A5: Process | B5: AS-IS - Proceso de gestión de pedidos de INDUPRO S.A.

Sheet Total cycle time
A1: Report | B1: Simulation
A2: Date | B2: 5/22/26
A3: Time | B3: 9:17 PM
A4: User | B4: Carlo Garcia
A5: Process | B5: AS-IS - Proceso de gestión de pedidos de INDUPRO S.A.
A8: The cycle time of a process instance is measured between its start and completion. The following table shows selected process instance cycle times as well as the total sum of all run cycles:
A10: Used scenario | B10: Duration in days | C10: Average | D10: Minimum | E10: Maximum | F10: Total cycle time
A11: Escenario 1 AS-IS | B11: 5 | C11: 0.59451389 | D11: 0.23263889 | E11: 1.7881944 | F11: 10.701389
A14: Execution times incl. waiting times
A15: The following table shows for each activity how long its execution took with respect to existing working schedules without taking available resources into account:
A17: Task | B17: Used scenario | C17: Duration in days | D17: Completed instances | E17: Average | F17: Minimum | G17: Maximum | H17: Total execution time
A18: Recibir solicitud del cliente | B18: Escenario 1 AS-IS | C18: 5 | D18: 20 | E18: 0.020833333 | F18: 0.020833333 | G18: 0.020833333 | H18: 0.41666667
A19: Validar datos del pedido | B19: Escenario 1 AS-IS | C19: 5 | D19: 20 | E19: 0.03125 | F19: 0.03125 | G19: 0.03125 | H19: 0.625
A20: Verificar crédito del cliente | B20: Escenario 1 AS-IS | C20: 5 | D20: 19 | E20: 0.18201389 | F20: 0.041666667 | G20: 0.70833333 | H20: 3.5
A21: Consultar disponibilidad de stock en bodega | B21: Escenario 1 AS-IS | C21: 5 | D21: 19 | E21: 0.034722222 | F21: 0.034722222 | G21: 0.034722222 | H21: 0.65972222
A22: Verificar stock | B22: Escenario 1 AS-IS | C22: 5 | D22: 19 | E22: 0.0034722222 | F22: 0.0034722222 | G22: 0.0034722222 | H22: 0.065972222
A23: Confirmar pedido al cliente | B23: Escenario 1 AS-IS | C23: 5 | D23: 18 | E23: 0.013888889 | F23: 0.013888889 | G23: 0.013888889 | H23: 0.25
A24: Programar orden de producción | B24: Escenario 1 AS-IS | C24: 5 | D24: 1 | E24: 0.027777778 | F24: 0.027777778 | G24: 0.027777778 | H24: 0.027777778
A25: Fabricar producto | B25: Escenario 1 AS-IS | C25: 5 | D25: 1 | E25: 0.083333333 | F25: 0.083333333 | G25: 0.083333333 | H25: 0.083333333
A26: Inspeccionar y liberar calidad | B26: Escenario 1 AS-IS | C26: 5 | D26: 1 | E26: 0.020833333 | F26: 0.020833333 | G26: 0.020833333 | H26: 0.020833333
A27: Verificar calidad | B27: Escenario 1 AS-IS | C27: 5 | D27: 1 | E27: 0.0034722222 | F27: 0.0034722222 | G27: 0.0034722222 | H27: 0.0034722222
A28: Reprocesar lote | B28: Escenario 1 AS-IS | C28: 5 | D28: 1 | E28: 0.0625 | F28: 0.0625 | G28: 0.0625 | H28: 0.0625
A29: Empacar y preparar para despacho | B29: Escenario 1 AS-IS | C29: 5 | D29: 18 | E29: 0.16550926 | F29: 0.017361111 | G29: 0.68402778 | H29: 3.0104167
... A32: Generar y enviar factura | B32: Escenario 1 AS-IS | C32: 5 | D32: 18 | E32: 0.013888889 | F32: 0.013888889 | G32: 0.013888889 | H32: 0.25
A35: Pure execution times
A36: Within a process instance, several activities are executed. This happens sub-sequentially, delayed or in parallel. The following table shows for each activity how long its pure execution took. The values ​​do not include any existing waiting times, those are included in the table at 'Execution times incl. waiting times'. Please note that waiting times due to missing resources are not displayed here, as they are analyzed under “Bottlenecks”.
A38: Task | B38: Used scenario | C38: Duration in days | D38: Completed instances | E38: Average | F38: Minimum | G38: Maximum | H38: Total execution time
A39: Recibir solicitud del cliente | B39: Escenario 1 AS-IS | C39: 5 | D39: 20 | E39: 0.020833333 | F39: 0.020833333 | G39: 0.020833333 | H39: 0.41666667
A40: Validar datos del pedido | B40: Escenario 1 AS-IS | C40: 5 | D40: 20 | E40: 0.03125 | F40: 0.03125 | G40: 0.03125 | H40: 0.625
A41: Verificar crédito del cliente | B41: Escenario 1 AS-IS | C41: 5 | D41: 19 | E41: 0.041666667 | F41: 0.041666667 | G41: 0.041666667 | H41: 0.83333333
A42: Consultar disponibilidad de stock en bodega | B42: Escenario 1 AS-IS | C42: 5 | D42: 19 | E42: 0.034722222 | F42: 0.034722222 | G42: 0.034722222 | H42: 0.65972222
A43: Verificar stock | B43: Escenario 1 AS-IS | C43: 5 | D43: 19 | E43: 0.0034722222 | F43: 0.0034722222 | G43: 0.0034722222 | H43: 0.065972222
A44: Confirmar pedido al cliente | B44: Escenario 1 AS-IS | C44: 5 | D44: 18 | E44: 0.013888889 | F44: 0.013888889 | G44: 0.013888889 | H44: 0.25
A45: Programar orden de producción | B45: Escenario 1 AS-IS | C45: 5 | D45: 1 | E45: 0.027777778 | F45: 0.027777778 | G45: 0.027777778 | H45: 0.027777778
A46: Fabricar producto | B46: Escenario 1 AS-IS | C46: 5 | D46: 1 | E46: 0.083333333 | F46: 0.083333333 | G46: 0.083333333 | H46: 0.083333333
A47: Inspeccionar y liberar calidad | B47: Escenario 1 AS-IS | C47: 5 | D47: 1 | E47: 0.020833333 | F47: 0.020833333 | G47: 0.020833333 | H47: 0.020833333
A48: Verificar calidad | B48: Escenario 1 AS-IS | C48: 5 | D48: 1 | E48: 0.0034722222 | F48: 0.0034722222 | G48: 0.0034722222 | H48: 0.0034722222
A49: Reprocesar lote | B49: Escenario 1 AS-IS | C49: 5 | D49: 1 | E49: 0.0625 | F49: 0.0625 | G49: 0.0625 | H49: 0.0625
A50: Empacar y preparar para despacho | B50: Escenario 1 AS-IS | C50: 5 | D50: 18 | E50: 0.017361111 | F50: 0.017361111 | G50: 0.017361111 | H50: 0.34375
... A53: Generar y enviar factura | B53: Escenario 1 AS-IS | C53: 5 | D53: 18 | E53: 0.013888889 | F53: 0.013888889 | G53: 0.013888889 | H53: 0.25
...

Sheet Total time chart
A1: Report | B1: Simulation
A2: Date | B2: 5/22/26
A3: Time | B3: 9:17 PM
A4: User | B4: Carlo Garcia
A5: Process | B5: AS-IS - Proceso de gestión de pedidos de INDUPRO S.A.

Sheet Resource consumption
A1: Report | B1: Simulation
A2: Date | B2: 5/22/26
A3: Time | B3: 9:17 PM
A4: User | B4: Carlo Garcia
A5: Process | B5: AS-IS - Proceso de gestión de pedidos de INDUPRO S.A.
A7: The execution of activities is performed by resources. The following table shows the workload of all resources in your scenario:
A10: Resources | B10: Used scenario | C10: Duration in days | D10: Consumed time | E10: Workload
A11: Ejecutivo de ventas | B11: Escenario 1 AS-IS | C11: 5 | D11: 1.2916667 | E11: 0.775
A12: Analista de finanzas | B12: Escenario 1 AS-IS | C12: 5 | D12: 1.0833333 | E12: 0.65
A13: Coordinador de Inventarios | B13: Escenario 1 AS-IS | C13: 5 | D13: 0.72569444 | E13: 0.4354
A14: Coordinador de logística | B14: Escenario 1 AS-IS | C14: 5 | D14: 0.70486111 | E14: 0.4229
A15: Transportista | B15: Escenario 1 AS-IS | C15: 5 | D15: 0.5625 | E15: 0.3375
A16: Operario de Planta | B16: Escenario 1 AS-IS | C16: 5 | D16: 0.14583333 | E16: 0.0875
A17: Planificador de Producción | B17: Escenario 1 AS-IS | C17: 5 | D17: 0.027777778 | E17: 0.0167
A18: Inspector de Calidad | B18: Escenario 1 AS-IS | C18: 5 | D18: 0.024305556 | E18: 0.0146
A20: Legend
A21: All values are relative to the highest value
A22: Latest run | B22: Previous run
A23: 100% | B23: 100%
A24: >87.5% | B24: >87.5%
A25: >75% | B25: >75%
A26: >62.5% | B26: >62.5%
A27: >50% | B27: >50%
A28: <=50% or smallest value | B28: <=50% or smallest value

Sheet Resource consumption chart
A1: Report | B1: Simulation
A2: Date | B2: 5/22/26
A3: Time | B3: 9:17 PM
A4: User | B4: Carlo Garcia
A5: Process | B5: AS-IS - Proceso de gestión de pedidos de INDUPRO S.A.

Sheet Bottlenecks
A1: Report | B1: Simulation
A2: Date | B2: 5/22/26
A3: Time | B3: 9:17 PM
A4: User | B4: Carlo Garcia
A5: Process | B5: AS-IS - Proceso de gestión de pedidos de INDUPRO S.A.
A7: The execution of a process instance might be delayed due to a shortage of resources: When an activity is ready for execution but all resources are already allocated, the execution has to wait. The following table shows activities that were delayed:
A10: Resources | B10: Task | C10: Used scenario | D10: Duration in days | E10: Total waiting time | F10: Instances waiting at termination
A11: Analista de finanzas | B11: Generar y enviar factura | C11: Escenario 1 AS-IS | D11: 5 | E11: 0.23611111 | F11: 0
B12: Verificar crédito del cliente | C12: Escenario 1 AS-IS | D12: 5 | E12: 0.13888889 | F12: 0
A14: Legend
A15: All values are relative to the highest value
A16: Latest run | B16: Previous run
A17: 100% | B17: 100%
A18: >87.5% | B18: >87.5%
A19: >75% | B19: >75%
A20: >62.5% | B20: >62.5%
A21: >50% | B21: >50%
A22: <=50% or smallest value | B22: <=50% or smallest value

Sheet Bottleneck chart
A1: Report | B1: Simulation
A2: Date | B2: 5/22/26
A3: Time | B3: 9:17 PM
A4: User | B4: Carlo Garcia
A5: Process | B5: AS-IS - Proceso de gestión de pedidos de INDUPRO S.A.

Sheet hiddenData
A1: =Costs!A16 | B1: =Costs!H16 | D1: ='Total cycle time'!H39 | F1: ='Resource consumption'!D11 | H1: =Bottlenecks!E11 | J1: Latest run Total costs
A2: =Costs!A17 | B2: =Costs!H17 | D2: ='Total cycle time'!H40 | F2: ='Resource consumption'!D12 | H2: =Bottlenecks!E12 | J2: Latest run Total cycle time
A3: =Costs!A18 | B3: =Costs!H18 | D3: ='Total cycle time'!H41 | F3: ='Resource consumption'!D13 | H3: =Bottlenecks!E13 | J3: Latest run Workload
A4: =Costs!A19 | B4: =Costs!H19 | D4: ='Total cycle time'!H42 | F4: ='Resource consumption'!D14 | H4: =Bottlenecks!E14 | J4: Latest run Total waiting time
A5: =Costs!A20 | B5: =Costs!H20 | D5: ='Total cycle time'!H43 | F5: ='Resource consumption'!D15 | H5: =Bottlenecks!E15
A6: =Costs!A21 | B6: =Costs!H21 | D6: ='Total cycle time'!H44 | F6: ='Resource consumption'!D16 | H6: =Bottlenecks!E16
A7: =Costs!A22 | B7: =Costs!H22 | D7: ='Total cycle time'!H45 | F7: ='Resource consumption'!D17 | H7: =Bottlenecks!E17
A8: =Costs!A23 | B8: =Costs!H23 | D8: ='Total cycle time'!H46 | F8: ='Resource consumption'!D18 | H8: =Bottlenecks!E18
A9: =Costs!A24 | B9: =Costs!H24 | D9: ='Total cycle time'!H47 | F9: ='Resource consumption'!A11 | H9: =Bottlenecks!E19
A10: =Costs!A25 | B10: =Costs!H25 | D10: ='Total cycle time'!H48 | F10: ='Resource consumption'!A12 | H10: =Bottlenecks!E20
A11: =Costs!A26 | B11: =Costs!H26 | D11: ='Total cycle time'!H49 | F11: ='Resource consumption'!A13 | H11: =Bottlenecks!E21
A12: =Costs!A27 | B12: =Costs!H27 | D12: ='Total cycle time'!H50 | F12: ='Resource consumption'!A14 | H12: =Bottlenecks!E22
A13: =Costs!A28 | B13: =Costs!H28 | D13: ='Total cycle time'!H51 | F13: ='Resource consumption'!A15 | H13: =Bottlenecks!E23
A14: =Costs!A29 | B14: =Costs!H29 | D14: ='Total cycle time'!H52 | F14: ='Resource consumption'!A16 | H14: =Bottlenecks!E24
A15: =Costs!A30 | B15: =Costs!H30 | D15: ='Total cycle time'!H53 | F15: ='Resource consumption'!A17 | H15: =Bottlenecks!E25
F16: ='Resource consumption'!A18

Sheet Scenario Escenario 1 AS-IS
A1: Report | B1: Simulation
A2: Date | B2: 5/22/26
A3: Time | B3: 9:17 PM
A4: User | B4: Carlo Garcia
A5: Process | B5: AS-IS - Proceso de gestión de pedidos de INDUPRO S.A.
A7: Costs and Duration
A9: Task | B9: Execution costs | C9: Execution time
A10: Recibir solicitud del cliente | B10: 0 | C10: 00h 30m
A11: Validar datos del pedido | B11: 0 | C11: 00h 45m
A12: Verificar crédito del cliente | B12: 0 | C12: 01h 00m
A13: Consultar disponibilidad de stock en bodega | B13: 0 | C13: 00h 50m
A14: Verificar stock | B14: 0 | C14: 00h 05m
A15: Confirmar pedido al cliente | B15: 0 | C15: 00h 20m
A16: Programar orden de producción | B16: 0 | C16: 00h 40m
A17: Fabricar producto | B17: 0 | C17: 02h 00m
A18: Inspeccionar y liberar calidad | B18: 0 | C18: 00h 30m
A19: Verificar calidad | B19: 0 | C19: 00h 05m
A20: Reprocesar lote | B20: 0 | C20: 01h 30m
A21: Empacar y preparar para despacho | B21: 0 | C21: 00h 25m
... A24: Generar y enviar factura | B24: 0 | C24: 00h 20m
A27: Frequency and probabilities
A29: Start event | B29: Frequency
A30: Llegada de Solicitud de pedido | B30: On Mon-Fri; overall 20 times
A32: Gateway | B32: Decision | C32: Probability
A33: Verificar stock | B33: No hay stock | C33: 0.18
B34: Sí hay stock | C34: 0.82
A35: Verificar calidad de producto | B35: APROBADA | C35: 0.65
B36: RECHAZADA | C36: 0.35
A39: Resources
A41: Role | B41: Work schedules | C41: Costs/hour
A42: Analista de finanzas | B42: 1 employees; 40 hours per week | C42: 13
A43: Coordinador de Inventarios | B43: 1 employees; 40 hours per week | C43: 10
A44: Coordinador de logística | B44: 1 employees; 40 hours per week | C44: 10
A45: Ejecutivo de ventas | B45: 1 employees; 40 hours per week | C45: 12
A46: Inspector de Calidad | B46: 1 employees; 40 hours per week | C46: 11
A47: Operario de Planta | B47: 1 employees; 40 hours per week | C47: 8
A48: Planificador de Producción | B48: 1 employees; 40 hours per week | C48: 14
A49: Transportista | B49: 1 employees; 40 hours per week | C49: 10
