Workbook
Name ActivityNames: hiddenData!$A$1:$A$12
Name Bottleneck0: #REF!
Name Bottleneck1: #REF!
Name Consumption0: hiddenData!$F$1:$F$9
Name Consumption1: #REF!
Name Resources: hiddenData!$F$10:$F$18
Name TotalCosts0: hiddenData!$B$1:$B$12
Name TotalCosts1: #REF!
Name TotalTime0: hiddenData!$D$1:$D$12
Name TotalTime1: #REF!

Sheet Overview
A1: Report | B1: Simulation
A2: Date | B2: 5/22/26
A3: Time | B3: 9:16 PM
A4: User | B4: Carlo Garcia
A5: Process | B5: TO-BE - Proceso de gestión de pedidos de INDUPRO S.A
A7: Used scenario | B7: Duration in days | C7: Total cycle time | D7: Resource consumption | E7: Bottlenecks
A8: Escenario 1 TO-BE | B8: 5 | C8: 1.8729167 | D8: 0.63611111

Sheet Costs
A1: Report | B1: Simulation
A2: Date | B2: 5/22/26
A3: Time | B3: 9:16 PM
A4: User | B4: Carlo Garcia
A5: Process | B5: TO-BE - Proceso de gestión de pedidos de INDUPRO S.A
A7: Execution costs of a process instance are the sum of fixed activity costs and resources costs. The latter ones are computed using defined responsibilities and activity execution durations. The following table shows selected process instance costs as well as the total sum of all costs:
A10: Used scenario | B10: Duration in days | C10: Average | D10: Minimum | E10: Maximum | F10: Total costs
A11: Escenario 1 TO-BE | B11: 5 | C11: 7.48 | D11: 2.08 | E11: 45.73 | F11: 147.72
A13: The following table shows the costs caused by every activity of your process:
A15: Task | B15: Used scenario | C15: Duration in days | D15: Completed instances | E15: Average | F15: Minimum | G15: Maximum | H15: Total costs
A16: Analizar pedido via portal web | B16: Escenario 1 TO-BE | C16: 5 | D16: 20 | E16: 1 | F16: 1 | G16: 1 | H16: 20
A17: Verificar credito del cliente via API financiera | B17: Escenario 1 TO-BE | C17: 5 | D17: 20 | E17: 1.08 | F17: 1.08 | G17: 1.08 | H17: 21.67
A18: Consultar disponibilidad de stock en ERP (tiempo real) | B18: Escenario 1 TO-BE | C18: 5 | D18: 7 | E18: 0.83 | F18: 0.83 | G18: 0.83 | H18: 5.83
A19: Programar orden de produccion en ERP digital | B19: Escenario 1 TO-BE | C19: 5 | D19: 2 | E19: 2.33 | F19: 2.33 | G19: 2.33 | H19: 4.67
A20: Fabricar el producto (con QC en proceso) | B20: Escenario 1 TO-BE | C20: 5 | D20: 2 | E20: 32 | F20: 32 | G20: 32 | H20: 64
A21: Inspeccionar calidad del lote (digital) | B21: Escenario 1 TO-BE | C21: 5 | D21: 2 | E21: 5.5 | F21: 5.5 | G21: 5.5 | H21: 11
A22: Enviar confirmacion automatica al cliente | B22: Escenario 1 TO-BE | C22: 5 | D22: 7 | E22: 0.2 | F22: 0.2 | G22: 0.2 | H22: 1.4
A23: Empacar y preparar para despacho | B23: Escenario 1 TO-BE | C23: 5 | D23: 7 | E23: 1.67 | F23: 1.67 | G23: 1.67 | H23: 11.67
A24: Asignar transportista via TMS automatizado | B24: Escenario 1 TO-BE | C24: 5 | D24: 7 | E24: 0.83 | F24: 0.83 | G24: 0.83 | H24: 5.83
A25: Entregar al cliente y registrar firma digital de conformidad | B25: Escenario 1 TO-BE | C25: 5 | D25: 6 | E25: 0.17 | F25: 0.17 | G25: 0.17 | H25: 1
A26: Generar y enviar factura electronica automatica | B26: Escenario 1 TO-BE | C26: 5 | D26: 6 | E26: 0.11 | F26: 0.11 | G26: 0.11 | H26: 0.65
A27: Reproceso de Calidad | B27: Escenario 1 TO-BE | C27: 5 | D27: 0 | E27: 0 | F27: 0 | G27: 0 | H27: 0
A29: Legend
A30: All values are relative to the highest value
A31: Latest run | B31: Previous run
A32: 100% | B32: 100%
A33: >87.5% | B33: >87.5%
A34: >75% | B34: >75%
A35: >62.5% | B35: >62.5%
A36: >50% | B36: >50%
A37: <=50% or smallest value | B37: <=50% or smallest value

Sheet Total cost chart
A1: Report | B1: Simulation
A2: Date | B2: 5/22/26
A3: Time | B3: 9:16 PM
A4: User | B4: Carlo Garcia
A5: Process | B5: TO-BE - Proceso de gestión de pedidos de INDUPRO S.A

Sheet Total cycle time
A1: Report | B1: Simulation
A2: Date | B2: 5/22/26
A3: Time | B3: 9:16 PM
A4: User | B4: Carlo Garcia
A5: Process | B5: TO-BE - Proceso de gestión de pedidos de INDUPRO S.A
A8: The cycle time of a process instance is measured between its start and completion. The following table shows selected process instance cycle times as well as the total sum of all run cycles:
A10: Used scenario | B10: Duration in days | C10: Average | D10: Minimum | E10: Maximum | F10: Total cycle time
A11: Escenario 1 TO-BE | B11: 5 | C11: 0.098564815 | D11: 0.0069444444 | E11: 0.83368056 | F11: 1.8729167
A14: Execution times incl. waiting times
A15: The following table shows for each activity how long its execution took with respect to existing working schedules without taking available resources into account:
A17: Task | B17: Used scenario | C17: Duration in days | D17: Completed instances | E17: Average | F17: Minimum | G17: Maximum | H17: Total execution time
A18: Analizar pedido via portal web | B18: Escenario 1 TO-BE | C18: 5 | D18: 20 | E18: 0.0034722222 | F18: 0.0034722222 | G18: 0.0034722222 | H18: 0.069444444
A19: Verificar credito del cliente via API financiera | B19: Escenario 1 TO-BE | C19: 5 | D19: 20 | E19: 0.0034722222 | F19: 0.0034722222 | G19: 0.0034722222 | H19: 0.069444444
A20: Consultar disponibilidad de stock en ERP (tiempo real) | B20: Escenario 1 TO-BE | C20: 5 | D20: 7 | E20: 0.0034722222 | F20: 0.0034722222 | G20: 0.0034722222 | H20: 0.024305556
A21: Programar orden de produccion en ERP digital | B21: Escenario 1 TO-BE | C21: 5 | D21: 2 | E21: 0.0069444444 | F21: 0.0069444444 | G21: 0.0069444444 | H21: 0.013888889
A22: Fabricar el producto (con QC en proceso) | B22: Escenario 1 TO-BE | C22: 5 | D22: 2 | E22: 0.083333333 | F22: 0.083333333 | G22: 0.083333333 | H22: 0.16666667
A23: Inspeccionar calidad del lote (digital) | B23: Escenario 1 TO-BE | C23: 5 | D23: 2 | E23: 0.020833333 | F23: 0.020833333 | G23: 0.020833333 | H23: 0.041666667
A24: Enviar confirmacion automatica al cliente | B24: Escenario 1 TO-BE | C24: 5 | D24: 7 | E24: 0.00069444444 | F24: 0.00069444444 | G24: 0.00069444444 | H24: 0.0048611111
A25: Empacar y preparar para despacho | B25: Escenario 1 TO-BE | C25: 5 | D25: 7 | E25: 0.0069444444 | F25: 0.0069444444 | G25: 0.0069444444 | H25: 0.048611111
A26: Asignar transportista via TMS automatizado | B26: Escenario 1 TO-BE | C26: 5 | D26: 7 | E26: 0.0034722222 | F26: 0.0034722222 | G26: 0.0034722222 | H26: 0.024305556
A27: Entregar al cliente y registrar firma digital de conformidad | B27: Escenario 1 TO-BE | C27: 5 | D27: 6 | E27: 0.21134259 | F27: 0.00069444444 | G27: 0.64652778 | H27: 1.2680556
A28: Generar y enviar factura electronica automatica | B28: Escenario 1 TO-BE | C28: 5 | D28: 6 | E28: 0.027893519 | F28: 0.00034722222 | G28: 0.082986111 | H28: 0.16736111
A29: Reproceso de Calidad | B29: Escenario 1 TO-BE | C29: 5 | D29: 0 | E29: 0 | F29: 0 | G29: 0 | H29: 0
A32: Pure execution times
A33: Within a process instance, several activities are executed. This happens sub-sequentially, delayed or in parallel. The following table shows for each activity how long its pure execution took. The values ​​do not include any existing waiting times, those are included in the table at 'Execution times incl. waiting times'. Please note that waiting times due to missing resources are not displayed here, as they are analyzed under “Bottlenecks”.
A35: Task | B35: Used scenario | C35: Duration in days | D35: Completed instances | E35: Average | F35: Minimum | G35: Maximum | H35: Total execution time
A36: Analizar pedido via portal web | B36: Escenario 1 TO-BE | C36: 5 | D36: 20 | E36: 0.0034722222 | F36: 0.0034722222 | G36: 0.0034722222 | H36: 0.069444444
A37: Verificar credito del cliente via API financiera | B37: Escenario 1 TO-BE | C37: 5 | D37: 20 | E37: 0.0034722222 | F37: 0.0034722222 | G37: 0.0034722222 | H37: 0.069444444
A38: Consultar disponibilidad de stock en ERP (tiempo real) | B38: Escenario 1 TO-BE | C38: 5 | D38: 7 | E38: 0.0034722222 | F38: 0.0034722222 | G38: 0.0034722222 | H38: 0.024305556
A39: Programar orden de produccion en ERP digital | B39: Escenario 1 TO-BE | C39: 5 | D39: 2 | E39: 0.0069444444 | F39: 0.0069444444 | G39: 0.0069444444 | H39: 0.013888889
A40: Fabricar el producto (con QC en proceso) | B40: Escenario 1 TO-BE | C40: 5 | D40: 2 | E40: 0.083333333 | F40: 0.083333333 | G40: 0.083333333 | H40: 0.16666667
A41: Inspeccionar calidad del lote (digital) | B41: Escenario 1 TO-BE | C41: 5 | D41: 2 | E41: 0.020833333 | F41: 0.020833333 | G41: 0.020833333 | H41: 0.041666667
A42: Enviar confirmacion automatica al cliente | B42: Escenario 1 TO-BE | C42: 5 | D42: 7 | E42: 0.00069444444 | F42: 0.00069444444 | G42: 0.00069444444 | H42: 0.0048611111
A43: Empacar y preparar para despacho | B43: Escenario 1 TO-BE | C43: 5 | D43: 7 | E43: 0.0069444444 | F43: 0.0069444444 | G43: 0.0069444444 | H43: 0.048611111
A44: Asignar transportista via TMS automatizado | B44: Escenario 1 TO-BE | C44: 5 | D44: 7 | E44: 0.0034722222 | F44: 0.0034722222 | G44: 0.0034722222 | H44: 0.024305556
A45: Entregar al cliente y registrar firma digital de conformidad | B45: Escenario 1 TO-BE | C45: 5 | D45: 6 | E45: 0.00069444444 | F45: 0.00069444444 | G45: 0.00069444444 | H45: 0.0041666667
A46: Generar y enviar factura electronica automatica | B46: Escenario 1 TO-BE | C46: 5 | D46: 6 | E46: 0.00034722222 | F46: 0.00034722222 | G46: 0.00034722222 | H46: 0.0020833333
A47: Reproceso de Calidad | B47: Escenario 1 TO-BE | C47: 5 | D47: 0 | E47: 0 | F47: 0 | G47: 0 | H47: 0
A49: Legend
A50: All values are relative to the highest value
...

Sheet Total time chart
A1: Report | B1: Simulation
A2: Date | B2: 5/22/26
A3: Time | B3: 9:16 PM
A4: User | B4: Carlo Garcia
A5: Process | B5: TO-BE - Proceso de gestión de pedidos de INDUPRO S.A

Sheet Resource consumption
A1: Report | B1: Simulation
A2: Date | B2: 5/22/26
A3: Time | B3: 9:16 PM
A4: User | B4: Carlo Garcia
A5: Process | B5: TO-BE - Proceso de gestión de pedidos de INDUPRO S.A
A7: The execution of activities is performed by resources. The following table shows the workload of all resources in your scenario:
A10: Resources | B10: Used scenario | C10: Duration in days | D10: Consumed time | E10: Workload
A11: Operario de QC en Proceso | B11: Escenario 1 TO-BE | C11: 5 | D11: 0.16666667 | E11: 0.5
A12: Coordinador de logística | B12: Escenario 1 TO-BE | C12: 5 | D12: 0.072916667 | E12: 0.0455
A13: Analista de finanzas | B13: Escenario 1 TO-BE | C13: 5 | D13: 0.071527778 | E13: 0.0446
A14: Ejecutivo de ventas | B14: Escenario 1 TO-BE | C14: 5 | D14: 0.074305556 | E14: 0.0232
A15: Operario de Planta | B15: Escenario 1 TO-BE | C15: 5 | D15: 0.16666667 | E15: 0.0173
A16: Coordinador de Inventarios | B16: Escenario 1 TO-BE | C16: 5 | D16: 0.024305556 | E16: 0.0152
A17: Inspector de Calidad | B17: Escenario 1 TO-BE | C17: 5 | D17: 0.041666667 | E17: 0.013
A18: Planificador de Producción | B18: Escenario 1 TO-BE | C18: 5 | D18: 0.013888889 | E18: 0.0087
A19: Transportista | B19: Escenario 1 TO-BE | C19: 5 | D19: 0.0041666667 | E19: 0.0029
A21: Legend
A22: All values are relative to the highest value
A23: Latest run | B23: Previous run
A24: 100% | B24: 100%
A25: >87.5% | B25: >87.5%
A26: >75% | B26: >75%
A27: >62.5% | B27: >62.5%
A28: >50% | B28: >50%
A29: <=50% or smallest value | B29: <=50% or smallest value

Sheet Resource consumption chart
A1: Report | B1: Simulation
A2: Date | B2: 5/22/26
A3: Time | B3: 9:16 PM
A4: User | B4: Carlo Garcia
A5: Process | B5: TO-BE - Proceso de gestión de pedidos de INDUPRO S.A

Sheet hiddenData
A1: =Costs!A16 | B1: =Costs!H16 | D1: ='Total cycle time'!H36 | F1: ='Resource consumption'!D11 | J1: Latest run Total costs
A2: =Costs!A17 | B2: =Costs!H17 | D2: ='Total cycle time'!H37 | F2: ='Resource consumption'!D12 | J2: Latest run Total cycle time
A3: =Costs!A18 | B3: =Costs!H18 | D3: ='Total cycle time'!H38 | F3: ='Resource consumption'!D13 | J3: Latest run Workload
A4: =Costs!A19 | B4: =Costs!H19 | D4: ='Total cycle time'!H39 | F4: ='Resource consumption'!D14
A5: =Costs!A20 | B5: =Costs!H20 | D5: ='Total cycle time'!H40 | F5: ='Resource consumption'!D15
A6: =Costs!A21 | B6: =Costs!H21 | D6: ='Total cycle time'!H41 | F6: ='Resource consumption'!D16
A7: =Costs!A22 | B7: =Costs!H22 | D7: ='Total cycle time'!H42 | F7: ='Resource consumption'!D17
A8: =Costs!A23 | B8: =Costs!H23 | D8: ='Total cycle time'!H43 | F8: ='Resource consumption'!D18
A9: =Costs!A24 | B9: =Costs!H24 | D9: ='Total cycle time'!H44 | F9: ='Resource consumption'!D19
A10: =Costs!A25 | B10: =Costs!H25 | D10: ='Total cycle time'!H45 | F10: ='Resource consumption'!A11
A11: =Costs!A26 | B11: =Costs!H26 | D11: ='Total cycle time'!H46 | F11: ='Resource consumption'!A12
A12: =Costs!A27 | B12: =Costs!H27 | D12: ='Total cycle time'!H47 | F12: ='Resource consumption'!A13
F13: ='Resource consumption'!A14
F14: ='Resource consumption'!A15
F15: ='Resource consumption'!A16
F16: ='Resource consumption'!A17
F17: ='Resource consumption'!A18
F18: ='Resource consumption'!A19

Sheet Scenario Escenario 1 TO-BE
A1: Report | B1: Simulation
A2: Date | B2: 5/22/26
A3: Time | B3: 9:16 PM
A4: User | B4: Carlo Garcia
A5: Process | B5: TO-BE - Proceso de gestión de pedidos de INDUPRO S.A
A7: Costs and Duration
A9: Task | B9: Execution costs | C9: Execution time
A10: Analizar pedido via portal web | B10: 0 | C10: 00h 05m
A11: Verificar credito del cliente via API financiera | B11: 0 | C11: 00h 05m
A12: Consultar disponibilidad de stock en ERP (tiempo real) | B12: 0 | C12: 00h 05m
A13: Programar orden de produccion en ERP digital | B13: 0 | C13: 00h 10m
A14: Fabricar el producto (con QC en proceso) | B14: 0 | C14: 02h 00m
A15: Inspeccionar calidad del lote (digital) | B15: 0 | C15: 00h 30m
A16: Enviar confirmacion automatica al cliente | B16: 0 | C16: 00h 01m
A17: Empacar y preparar para despacho | B17: 0 | C17: 00h 10m
A18: Asignar transportista via TMS automatizado | B18: 0 | C18: 00h 05m
A19: Entregar al cliente y registrar firma digital de conformidad | B19: 0 | C19: 00h 01m
A20: Generar y enviar factura electronica automatica | B20: 0 | C20: 00h 00m 30s
A21: Reproceso de Calidad | B21: 0 | C21: 00h 30m
A24: Frequency and probabilities
A26: Start event | B26: Frequency
A27: Solicitud de pedido (portal web) | B27: On Mon-Fri; overall 20 times
A29: Gateway | B29: Decision | C29: Probability
A30: Verificar crédito | B30: Aprobado | C30: 0.5
B31: Desaprobado | C31: 0.5
A32: Verificar stock | B32: No hay stock (30%) | C32: 0.3
B33: Sí hay stock (70%) | C33: 0.7
A34: Verificar control de calidad | B34: No aprueba (5%) | C34: 0.05
B35: Sí aprueba (95%) | C35: 0.95
A38: Resources
A40: Role | B40: Work schedules | C40: Costs/hour
A41: Analista de finanzas | B41: 1 employees; 40 hours per week | C41: 13
A42: Coordinador de Inventarios | B42: 1 employees; 40 hours per week | C42: 10
A43: Coordinador de logística | B43: 1 employees; 40 hours per week | C43: 10
A44: Ejecutivo de ventas | B44: 2 employees; 80 hours per week | C44: 12
A45: Inspector de Calidad | B45: 2 employees; 80 hours per week | C45: 11
A46: Operario de Planta | B46: 6 employees; 240 hours per week | C46: 8
A47: Operario de QC en Proceso | B47: 1 employees; 8 hours per week | C47: 8
A48: Planificador de Producción | B48: 1 employees; 40 hours per week | C48: 14
A49: Transportista | B49: 1 employees; 35 hours per week | C49: 10
